[2024-03-22T06:11:36.242+0000] {taskinstance.py:1979} INFO - Dependencies all met for dep_context=non-requeueable deps ti=<TaskInstance: fetch_articles_workflow.process_and_save manual__2024-03-22T06:11:23.257232+00:00 [queued]>
[2024-03-22T06:11:36.256+0000] {taskinstance.py:1979} INFO - Dependencies all met for dep_context=requeueable deps ti=<TaskInstance: fetch_articles_workflow.process_and_save manual__2024-03-22T06:11:23.257232+00:00 [queued]>
[2024-03-22T06:11:36.257+0000] {taskinstance.py:2193} INFO - Starting attempt 1 of 2
[2024-03-22T06:11:36.276+0000] {taskinstance.py:2217} INFO - Executing <Task(_PythonDecoratedOperator): process_and_save> on 2024-03-22 06:11:23.257232+00:00
[2024-03-22T06:11:36.283+0000] {standard_task_runner.py:60} INFO - Started process 669 to run task
[2024-03-22T06:11:36.292+0000] {standard_task_runner.py:87} INFO - Running: ['***', 'tasks', 'run', 'fetch_articles_workflow', 'process_and_save', 'manual__2024-03-22T06:11:23.257232+00:00', '--job-id', '5', '--raw', '--subdir', 'DAGS_FOLDER/fetch_articles.py', '--cfg-path', '/tmp/tmph58hwa_2']
[2024-03-22T06:11:36.296+0000] {standard_task_runner.py:88} INFO - Job 5: Subtask process_and_save
[2024-03-22T06:11:36.450+0000] {task_command.py:423} INFO - Running <TaskInstance: fetch_articles_workflow.process_and_save manual__2024-03-22T06:11:23.257232+00:00 [running]> on host 1b79855aa23a
[2024-03-22T06:11:37.094+0000] {taskinstance.py:2513} INFO - Exporting env vars: AIRFLOW_CTX_DAG_EMAIL='mitchomzz@gmail.com' AIRFLOW_CTX_DAG_OWNER='***' AIRFLOW_CTX_DAG_ID='fetch_articles_workflow' AIRFLOW_CTX_TASK_ID='process_and_save' AIRFLOW_CTX_EXECUTION_DATE='2024-03-22T06:11:23.257232+00:00' AIRFLOW_CTX_TRY_NUMBER='1' AIRFLOW_CTX_DAG_RUN_ID='manual__2024-03-22T06:11:23.257232+00:00'
[2024-03-22T06:11:39.759+0000] {logging_mixin.py:188} INFO - Failed to fetch articles. Status code: 414
[2024-03-22T06:11:39.804+0000] {taskinstance.py:2731} ERROR - Task failed with exception
Traceback (most recent call last):
  File "/home/airflow/.local/lib/python3.8/site-packages/pandas/core/indexes/base.py", line 3653, in get_loc
    return self._engine.get_loc(casted_key)
  File "pandas/_libs/index.pyx", line 147, in pandas._libs.index.IndexEngine.get_loc
  File "pandas/_libs/index.pyx", line 176, in pandas._libs.index.IndexEngine.get_loc
  File "pandas/_libs/hashtable_class_helper.pxi", line 7080, in pandas._libs.hashtable.PyObjectHashTable.get_item
  File "pandas/_libs/hashtable_class_helper.pxi", line 7088, in pandas._libs.hashtable.PyObjectHashTable.get_item
KeyError: 'timestamp'

The above exception was the direct cause of the following exception:

Traceback (most recent call last):
  File "/home/airflow/.local/lib/python3.8/site-packages/airflow/models/taskinstance.py", line 444, in _execute_task
    result = _execute_callable(context=context, **execute_callable_kwargs)
  File "/home/airflow/.local/lib/python3.8/site-packages/airflow/models/taskinstance.py", line 414, in _execute_callable
    return execute_callable(context=context, **execute_callable_kwargs)
  File "/home/airflow/.local/lib/python3.8/site-packages/airflow/decorators/base.py", line 241, in execute
    return_value = super().execute(context)
  File "/home/airflow/.local/lib/python3.8/site-packages/airflow/operators/python.py", line 200, in execute
    return_value = self.execute_callable()
  File "/home/airflow/.local/lib/python3.8/site-packages/airflow/operators/python.py", line 217, in execute_callable
    return self.python_callable(*self.op_args, **self.op_kwargs)
  File "/opt/airflow/dags/fetch_articles.py", line 48, in process_and_save
    store_articles(data)
  File "/opt/airflow/dags/blob_storage.py", line 30, in store_articles
    df['timestamp'] = pd.to_datetime(df['timestamp'])
  File "/home/airflow/.local/lib/python3.8/site-packages/pandas/core/frame.py", line 3761, in __getitem__
    indexer = self.columns.get_loc(key)
  File "/home/airflow/.local/lib/python3.8/site-packages/pandas/core/indexes/base.py", line 3655, in get_loc
    raise KeyError(key) from err
KeyError: 'timestamp'
[2024-03-22T06:11:39.954+0000] {taskinstance.py:1149} INFO - Marking task as UP_FOR_RETRY. dag_id=fetch_articles_workflow, task_id=process_and_save, execution_date=20240322T061123, start_date=20240322T061136, end_date=20240322T061139
[2024-03-22T06:11:40.062+0000] {standard_task_runner.py:107} ERROR - Failed to execute job 5 for task process_and_save ('timestamp'; 669)
[2024-03-22T06:11:40.242+0000] {local_task_job_runner.py:234} INFO - Task exited with return code 1
[2024-03-22T06:11:40.480+0000] {taskinstance.py:3312} INFO - 0 downstream tasks scheduled from follow-on schedule check
